[2022-11-27T09:48:47.241+0000] {taskinstance.py:1165} INFO - Dependencies all met for <TaskInstance: saham_one_time_historical.insert_table_saham manual__2022-11-27T09:47:10.422410+00:00 [queued]>
[2022-11-27T09:48:47.640+0000] {taskinstance.py:1165} INFO - Dependencies all met for <TaskInstance: saham_one_time_historical.insert_table_saham manual__2022-11-27T09:47:10.422410+00:00 [queued]>
[2022-11-27T09:48:47.648+0000] {taskinstance.py:1362} INFO - 
--------------------------------------------------------------------------------
[2022-11-27T09:48:47.651+0000] {taskinstance.py:1363} INFO - Starting attempt 1 of 4
[2022-11-27T09:48:47.669+0000] {taskinstance.py:1364} INFO - 
--------------------------------------------------------------------------------
[2022-11-27T09:48:48.128+0000] {taskinstance.py:1383} INFO - Executing <Task(PythonOperator): insert_table_saham> on 2022-11-27 09:47:10.422410+00:00
[2022-11-27T09:48:48.222+0000] {standard_task_runner.py:55} INFO - Started process 313 to run task
[2022-11-27T09:48:48.314+0000] {standard_task_runner.py:82} INFO - Running: ['***', 'tasks', 'run', 'saham_one_time_historical', 'insert_table_saham', 'manual__2022-11-27T09:47:10.422410+00:00', '--job-id', '17', '--raw', '--subdir', 'DAGS_FOLDER/one_time_historical_dag.py', '--cfg-path', '/tmp/tmpuszxu23i']
[2022-11-27T09:48:48.379+0000] {standard_task_runner.py:83} INFO - Job 17: Subtask insert_table_saham
[2022-11-27T09:48:57.532+0000] {task_command.py:376} INFO - Running <TaskInstance: saham_one_time_historical.insert_table_saham manual__2022-11-27T09:47:10.422410+00:00 [running]> on host 3cef85d75852
[2022-11-27T09:48:59.014+0000] {taskinstance.py:1592} INFO - Exporting the following env vars:
AIRFLOW_CTX_DAG_OWNER=kcb kelompok
AIRFLOW_CTX_DAG_ID=saham_one_time_historical
AIRFLOW_CTX_TASK_ID=insert_table_saham
AIRFLOW_CTX_EXECUTION_DATE=2022-11-27T09:47:10.422410+00:00
AIRFLOW_CTX_TRY_NUMBER=1
AIRFLOW_CTX_DAG_RUN_ID=manual__2022-11-27T09:47:10.422410+00:00
[2022-11-27T09:48:59.187+0000] {taskinstance.py:1851} ERROR - Task failed with exception
Traceback (most recent call last):
  File "/home/airflow/.local/lib/python3.7/site-packages/airflow/operators/python.py", line 175, in execute
    return_value = self.execute_callable()
  File "/home/airflow/.local/lib/python3.7/site-packages/airflow/operators/python.py", line 193, in execute_callable
    return self.python_callable(*self.op_args, **self.op_kwargs)
  File "/opt/airflow/one_time_historical/extract_dim_saham.py", line 53, in insertStockListData
    data = getstocklistData()
  File "/opt/airflow/one_time_historical/extract_dim_saham.py", line 19, in getstocklistData
    data = get_scrap_data(URL)
  File "/opt/airflow/one_time_historical/utils.py", line 46, in get_scrap_data
    options=options)
  File "/home/airflow/.local/lib/python3.7/site-packages/selenium/webdriver/remote/webdriver.py", line 288, in __init__
    self.start_session(capabilities, browser_profile)
  File "/home/airflow/.local/lib/python3.7/site-packages/selenium/webdriver/remote/webdriver.py", line 381, in start_session
    response = self.execute(Command.NEW_SESSION, parameters)
  File "/home/airflow/.local/lib/python3.7/site-packages/selenium/webdriver/remote/webdriver.py", line 442, in execute
    response = self.command_executor.execute(driver_command, params)
  File "/home/airflow/.local/lib/python3.7/site-packages/selenium/webdriver/remote/remote_connection.py", line 294, in execute
    return self._request(command_info[0], url, body=data)
  File "/home/airflow/.local/lib/python3.7/site-packages/selenium/webdriver/remote/remote_connection.py", line 316, in _request
    response = self._conn.request(method, url, body=body, headers=headers)
  File "/home/airflow/.local/lib/python3.7/site-packages/urllib3/request.py", line 79, in request
    method, url, fields=fields, headers=headers, **urlopen_kw
  File "/home/airflow/.local/lib/python3.7/site-packages/urllib3/request.py", line 170, in request_encode_body
    return self.urlopen(method, url, **extra_kw)
  File "/home/airflow/.local/lib/python3.7/site-packages/urllib3/poolmanager.py", line 365, in urlopen
    conn = self.connection_from_host(u.host, port=u.port, scheme=u.scheme)
  File "/home/airflow/.local/lib/python3.7/site-packages/urllib3/poolmanager.py", line 237, in connection_from_host
    raise LocationValueError("No host specified.")
urllib3.exceptions.LocationValueError: No host specified.
[2022-11-27T09:48:59.319+0000] {taskinstance.py:1406} INFO - Marking task as UP_FOR_RETRY. dag_id=saham_one_time_historical, task_id=insert_table_saham, execution_date=20221127T094710, start_date=20221127T094847, end_date=20221127T094859
[2022-11-27T09:48:59.425+0000] {standard_task_runner.py:105} ERROR - Failed to execute job 17 for task insert_table_saham (No host specified.; 313)
[2022-11-27T09:48:59.645+0000] {local_task_job.py:159} INFO - Task exited with return code 1
[2022-11-27T09:48:59.981+0000] {taskinstance.py:2623} INFO - 0 downstream tasks scheduled from follow-on schedule check
